Workbook

Sheet Calc
A1: Product | B1: Container Volume (L) | C1: Glass Color | D1: Sales Country | E1: Unit of Measure | F1: Quantity Sold | G1: Unit Weight (kg) | H1: Total Weight (tons) | I1: Average Selling Price per Unit (BYN) | J1: Average Selling Price per Ton (BYN) | K1: Net Revenue, excl. VAT (BYN) | L1: Gross Revenue, incl. VAT (BYN) | M1: Manufacturing Cost (BYN) | N1: Administrative Expenses (BYN) | O1: Selling Expenses (BYN) | P1: Total Cost (BYN) | Q1: Unit Cost (BYN) | R1: Cost per Ton (BYN) | S1: Operating Profit (BYN) | T1: Product Profitability (%) | U1: Profit Margin (%)
A2: Bottle 32-П-29-А-700 | B2: 0.7 | C2: Colored | D2: Azerbaijan | E2: pcs | F2: 34560 | G2: 0.45 | H2: =F2*G2/1000 -> 15.552 | I2: =K2/F2 -> 0.36047193 | J2: =K2/H2 -> 801.04874 | K2: 12457.91 | L2: 12457.91 | M2: 9599.58 | N2: 1343.77 | O2: 274.13 | P2: =SUM(M2:O2) -> 11217.48 | Q2: =P2/F2 -> 0.32457986 | R2: =P2/H2 -> 721.28858 | S2: =K2-P2 -> 1240.43 | T2: =S2/P2 -> 0.11058009 | U2: =S2/K2 -> 0.099569671
A3: Bottle 123-КПШ | B3: 0.75 | C3: Clear | D3: Lithuania | E3: pcs | F3: 163800 | G3: 0.7 | H3: =F3*G3/1000 -> 114.66 | I3: =K3/F3 -> 0.62781404 | J3: =K3/H3 -> 896.8772 | K3: 102835.94 | L3: 102835.94 | M3: 81448.82 | N3: 9907.24 | O3: 2021.11 | P3: =SUM(M3:O3) -> 93377.17 | Q3: =P3/F3 -> 0.57006819 | R3: =P3/H3 -> 814.38313 | S3: =K3-P3 -> 9458.77 | T3: =S3/P3 -> 0.10129639 | U3: =S3/K3 -> 0.091979224
A4: Bottle 11-ВКП-2 | B4: 0.5 | C4: Colored | D4: Russia | E4: pcs | F4: 152364 | G4: 0.33 | H4: =F4*G4/1000 -> 50.28012 | I4: =K4/F4 -> 0.255 | J4: =K4/H4 -> 772.72727 | K4: 38852.82 | L4: =K4 -> 38852.82 | M4: =M15/F15*F4 -> 34734.917 | N4: =M4*13.5% -> 4689.2138 | O4: =M4*3% -> 1042.0475 | P4: =SUM(M4:O4) -> 40466.179 | Q4: =P4/F4 -> 0.26558884 | R4: =P4/H4 -> 804.81468 | S4: =K4-P4 -> -1613.3587 | T4: =S4/P4 -> -0.039869313 | U4: =S4/K4 -> -0.041524881
A5: Bottle 32-П-29-А-700 | B5: 0.7 | C5: Colored | D5: Russia | E5: pcs | F5: 256980 | G5: 0.45 | H5: =F5*G5/1000 -> 115.641 | I5: =K5/F5 -> 0.36 | J5: =K5/H5 -> 800 | K5: 92512.8 | L5: =K5 -> 92512.8 | M5: =M16/F16*F5 -> 71380.175 | N5: =M5*13.5% -> 9636.3236 | O5: =M5*3% -> 2141.4053 | P5: =SUM(M5:O5) -> 83157.904 | Q5: =P5/F5 -> 0.32359679 | R5: =P5/H5 -> 719.10398 | S5: =K5-P5 -> 9354.8961 | T5: =S5/P5 -> 0.11249557 | U5: =S5/K5 -> 0.10112002
A6: Bottle 42-КПШ | B6: 0.375 | C6: Colored | D6: Russia | E6: pcs | F6: 25630 | G6: 0.457 | H6: =F6*G6/1000 -> 11.71291 | I6: =K6/F6 -> 0.41 | J6: =K6/H6 -> 897.15536 | K6: 10508.3 | L6: =K6 -> 10508.3 | M6: =M17/F17*F6 -> 7190.453 | N6: =M6*13.5% -> 970.71115 | O6: =M6*3% -> 215.71359 | P6: =SUM(M6:O6) -> 8376.8777 | Q6: =P6/F6 -> 0.32683877 | R6: =P6/H6 -> 715.18331 | S6: =K6-P6 -> 2131.4223 | T6: =S6/P6 -> 0.25444114 | U6: =S6/K6 -> 0.20283227
A7: Bottle 138-КПНн | B7: 0.568 | C7: Colored | D7: Russia | E7: pcs | F7: 24960 | G7: 0.37 | H7: =F7*G7/1000 -> 9.2352 | I7: =K7/F7 -> 0.27400641 | J7: =K7/H7 -> 740.55787 | K7: 6839.2 | L7: =K7 -> 6839.2 | M7: =M18/F18*F7 -> 6121.5943 | N7: =M7*13.5% -> 826.41523 | O7: =M7*3% -> 183.64783 | P7: =SUM(M7:O7) -> 7131.6574 | Q7: =P7/F7 -> 0.28572345 | R7: =P7/H7 -> 772.22555 | S7: =K7-P7 -> -292.45737 | T7: =S7/P7 -> -0.041008331 | U7: =S7/K7 -> -0.042761926
A8: Bottle 109-А | B8: 0.5 | C8: Clear | D8: Russia | E8: pcs | F8: 28900 | G8: 0.35 | H8: =F8*G8/1000 -> 10.115 | I8: =K8/F8 -> 0.3 | J8: =K8/H8 -> 857.14286 | K8: 8670 | L8: =K8 -> 8670 | M8: =M19/F19*F8 -> 7114.4881 | N8: =M8*13.5% -> 960.4559 | O8: =M8*3% -> 213.43464 | P8: =SUM(M8:O8) -> 8288.3787 | Q8: =P8/F8 -> 0.28679511 | R8: =P8/H8 -> 819.4146 | S8: =K8-P8 -> 381.62131 | T8: =S8/P8 -> 0.046042939 | U8: =S8/K8 -> 0.044016299
A9: Bottle 111-В | B9: 0.5 | C9: Colored | D9: Poland | E9: pcs | F9: 156000 | G9: 0.53 | H9: =F9*G9/1000 -> 82.68 | I9: =K9/F9 -> 0.37 | J9: =K9/H9 -> 698.11321 | K9: 57720 | L9: =K9 -> 57720 | M9: =M20/F20*F9 -> 51229.844 | N9: =M9*13.5% -> 6916.029 | O9: =M9*3% -> 1536.8953 | P9: =SUM(M9:O9) -> 59682.769 | Q9: =P9/F9 -> 0.38258185 | R9: =P9/H9 -> 721.85255 | S9: =K9-P9 -> -1962.7688 | T9: =S9/P9 -> -0.032886691 | U9: =S9/K9 -> -0.034005003
A10: Bottle 115-КПНб | B10: 0.5 | C10: Colored | D10: Poland | E10: pcs | F10: 483500 | G10: 0.345 | H10: =F10*G10/1000 -> 166.8075 | I10: =K10/F10 -> 0.26 | J10: =K10/H10 -> 753.62319 | K10: 125710 | L10: =K10 -> 125710 | M10: =M21/F21*F10 -> 100424.9 | N10: =M10*13.5% -> 13557.361 | O10: =M10*3% -> 3012.7469 | P10: =SUM(M10:O10) -> 116995 | Q10: =P10/F10 -> 0.24197519 | R10: =P10/H10 -> 701.37736 | S10: =K10-P10 -> 8714.996 | T10: =S10/P10 -> 0.074490326 | U10: =S10/K10 -> 0.069326195
A11: Bottle 118-ВВК | B11: 0.5 | C11: Clear | D11: Poland | E11: pcs | F11: 259320 | G11: 0.51 | H11: =F11*G11/1000 -> 132.2532 | I11: =K11/F11 -> 0.36 | J11: =K11/H11 -> 705.88235 | K11: 93355.2 | L11: =K11 -> 93355.2 | M11: =M22/F22*F11 -> 87828.415 | N11: =M11*13.5% -> 11856.836 | O11: =M11*3% -> 2634.8525 | P11: =SUM(M11:O11) -> 102320.1 | Q11: =P11/F11 -> 0.39457081 | R11: =P11/H11 -> 773.66826 | S11: =K11-P11 -> -8964.9036 | T11: =S11/P11 -> -0.087616248 | U11: =S11/K11 -> -0.09603004
A12: Bottle 125-В | B12: 0.5 | C12: Clear | D12: Poland | E12: pcs | F12: 763980 | G12: 0.415 | H12: =F12*G12/1000 -> 317.0517 | I12: =K12/F12 -> 0.35 | J12: =K12/H12 -> 843.37349 | K12: 267393 | L12: =K12 -> 267393 | M12: =M23/F23*F12 -> 217151.43 | N12: =M12*13.5% -> 29315.443 | O12: =M12*3% -> 6514.5428 | P12: =SUM(M12:O12) -> 252981.41 | Q12: =P12/F12 -> 0.33113617 | R12: =P12/H12 -> 797.91849 | S12: =K12-P12 -> 14411.586 | T12: =S12/P12 -> 0.056966977 | U12: =S12/K12 -> 0.053896648
A13: Bottle 126-В | B13: 0.5 | C13: Clear | D13: Latvia | E13: pcs | F13: 85620 | G13: 0.445 | H13: =F13*G13/1000 -> 38.1009 | I13: =K13/F13 -> 0.375 | J13: =K13/H13 -> 842.69663 | K13: 32107.5 | L13: =K13 -> 32107.5 | M13: =M24/F24*F13 -> 28639.952 | N13: =M13*13.5% -> 3866.3935 | O13: =M13*3% -> 859.19856 | P13: =SUM(M13:O13) -> 33365.544 | Q13: =P13/F13 -> 0.38969334 | R13: =P13/H13 -> 875.71538 | S13: =K13-P13 -> -1258.044 | T13: =S13/P13 -> -0.037704886 | U13: =S13/K13 -> -0.039182248
A14: Bottle 128-КПН-М | B14: 0.5 | C14: Colored | D14: Latvia | E14: pcs | F14: 256300 | G14: 0.33 | H14: =F14*G14/1000 -> 84.579 | I14: =K14/F14 -> 0.255 | J14: =K14/H14 -> 772.72727 | K14: 65356.5 | L14: =K14 -> 65356.5 | M14: =M25/F25*F14 -> 52091.432 | N14: =M14*13.5% -> 7032.3433 | O14: =M14*3% -> 1562.743 | P14: =SUM(M14:O14) -> 60686.518 | Q14: =P14/F14 -> 0.23677924 | R14: =P14/H14 -> 717.51284 | S14: =K14-P14 -> 4669.9815 | T14: =S14/P14 -> 0.076952537 | U14: =S14/K14 -> 0.071453972
A15: Bottle 11-ВКП-2 | B15: 0.5 | C15: Colored | D15: Belarus | E15: pcs | F15: 46592 | G15: 0.33 | H15: =F15*G15/1000 -> 15.37536 | I15: =K15/F15 -> 0.25 | J15: =K15/H15 -> 757.57576 | K15: 11648 | L15: 13977.6 | M15: 10621.73 | N15: 1328.51 | O15: 271.02 | P15: =SUM(M15:O15) -> 12221.26 | Q15: =P15/F15 -> 0.26230383 | R15: =P15/H15 -> 794.86009 | S15: =K15-P15 -> -573.26 | T15: =S15/P15 -> -0.046906784 | U15: =S15/K15 -> -0.049215316
A16: Bottle 32-П-29-А-700 | B16: 0.7 | C16: Colored | D16: Belarus | E16: pcs | F16: 200160 | G16: 0.45 | H16: =F16*G16/1000 -> 90.072 | I16: =K16/F16 -> 0.36 | J16: =K16/H16 -> 800 | K16: 72057.6 | L16: 86469.12 | M16: 55597.54 | N16: 7782.67 | O16: 1587.66 | P16: =SUM(M16:O16) -> 64967.87 | Q16: =P16/F16 -> 0.32457969 | R16: =P16/H16 -> 721.28819 | S16: =K16-P16 -> 7089.73 | T16: =S16/P16 -> 0.10912671 | U16: =S16/K16 -> 0.09838976
A17: Bottle 42-КПШ | B17: 0.375 | C17: Colored | D17: Belarus | E17: pcs | F17: 85008 | G17: 0.457 | H17: =F17*G17/1000 -> 38.848656 | I17: =K17/F17 -> 0.4 | J17: =K17/H17 -> 875.27352 | K17: 34003.2 | L17: 40803.84 | M17: 23848.85 | N17: 3356.72 | O17: 684.78 | P17: =SUM(M17:O17) -> 27890.35 | Q17: =P17/F17 -> 0.32809089 | R17: =P17/H17 -> 717.92316 | S17: =K17-P17 -> 6112.85 | T17: =S17/P17 -> 0.21917437 | U17: =S17/K17 -> 0.17977279
A18: Bottle 138-КПНн | B18: 0.568 | C18: Colored | D18: Belarus | E18: pcs | F18: 170816 | G18: 0.37 | H18: =F18*G18/1000 -> 63.20192 | I18: =K18/F18 -> 0.27 | J18: =K18/H18 -> 729.72973 | K18: 46120.32 | L18: 55344.39 | M18: 41893.68 | N18: 5460.98 | O18: 1114.05 | P18: =SUM(M18:O18) -> 48468.71 | Q18: =P18/F18 -> 0.28374807 | R18: =P18/H18 -> 766.88667 | S18: =K18-P18 -> -2348.39 | T18: =S18/P18 -> -0.048451671 | U18: =S18/K18 -> -0.050918771
A19: Bottle 109-А | B19: 0.5 | C19: Clear | D19: Belarus | E19: pcs | F19: 107520 | G19: 0.35 | H19: =F19*G19/1000 -> 37.632 | I19: =K19/F19 -> 0.29 | J19: =K19/H19 -> 828.57143 | K19: 31180.8 | L19: 37416.96 | M19: 26468.85 | N19: 3251.59 | O19: 663.33 | P19: =SUM(M19:O19) -> 30383.77 | Q19: =P19/F19 -> 0.28258715 | R19: =P19/H19 -> 807.39185 | S19: =K19-P19 -> 797.03 | T19: =S19/P19 -> 0.026232097 | U19: =S19/K19 -> 0.025561564
A20: Bottle 111-В | B20: 0.5 | C20: Colored | D20: Belarus | E20: pcs | F20: 140400 | G20: 0.53 | H20: =F20*G20/1000 -> 74.412 | I20: =K20/F20 -> 0.37 | J20: =K20/H20 -> 698.11321 | K20: 51948 | L20: 62337.6 | M20: 46106.86 | N20: 6429.59 | O20: 1311.64 | P20: =SUM(M20:O20) -> 53848.09 | Q20: =P20/F20 -> 0.3835334 | R20: =P20/H20 -> 723.64793 | S20: =K20-P20 -> -1900.09 | T20: =S20/P20 -> -0.035286117 | U20: =S20/K20 -> -0.036576769
A21: Bottle 115-КПНб | B21: 0.5 | C21: Colored | D21: Belarus | E21: pcs | F21: 480480 | G21: 0.345 | H21: =F21*G21/1000 -> 165.7656 | I21: =K21/F21 -> 0.25 | J21: =K21/H21 -> 724.63768 | K21: 120120 | L21: 144144 | M21: 99797.63 | N21: 14323 | O21: 2921.9 | P21: =SUM(M21:O21) -> 117042.53 | Q21: =P21/F21 -> 0.24359501 | R21: =P21/H21 -> 706.07249 | S21: =K21-P21 -> 3077.47 | T21: =S21/P21 -> 0.026293605 | U21: =S21/K21 -> 0.025619963
A22: Bottle 118-ВВК | B22: 0.5 | C22: Clear | D22: Belarus | E22: pcs | F22: 264992 | G22: 0.51 | H22: =F22*G22/1000 -> 135.14592 | I22: =K22/F22 -> 0.36 | J22: =K22/H22 -> 705.88235 | K22: 95397.12 | L22: 114476.53 | M22: 89749.45 | N22: 11677.33 | O22: 2382.17 | P22: =SUM(M22:O22) -> 103808.95 | Q22: =P22/F22 -> 0.39174371 | R22: =P22/H22 -> 768.12493 | S22: =K22-P22 -> -8411.83 | T22: =S22/P22 -> -0.081031838 | U22: =S22/K22 -> -0.088176981
A23: Bottle 125-В | B23: 0.5 | C23: Clear | D23: Belarus | E23: pcs | F23: 99680 | G23: 0.415 | H23: =F23*G23/1000 -> 41.3672 | I23: =K23/F23 -> 0.35 | J23: =K23/H23 -> 843.37349 | K23: 34888 | L23: 41865.6 | M23: 28332.75 | N23: 3574.33 | O23: 729.17 | P23: =SUM(M23:O23) -> 32636.25 | Q23: =P23/F23 -> 0.32741021 | R23: =P23/H23 -> 788.94027 | S23: =K23-P23 -> 2251.75 | T23: =S23/P23 -> 0.068995366 | U23: =S23/K23 -> 0.064542249
A24: Bottle 126-В | B24: 0.5 | C24: Clear | D24: Belarus | E24: pcs | F24: 193440 | G24: 0.445 | H24: =F24*G24/1000 -> 86.0808 | I24: =K24/F24 -> 0.37 | J24: =K24/H24 -> 831.46067 | K24: 71572.8 | L24: 85887.36 | M24: 64705.82 | N24: 7437.81 | O24: 1517.33 | P24: =SUM(M24:O24) -> 73660.96 | Q24: =P24/F24 -> 0.38079487 | R24: =P24/H24 -> 855.71881 | S24: =K24-P24 -> -2088.16 | T24: =S24/P24 -> -0.028348259 | U24: =S24/K24 -> -0.029175329
A25: Bottle 128-КПН-М | B25: 0.5 | C25: Colored | D25: Belarus | E25: pcs | F25: 99008 | G25: 0.33 | H25: =F25*G25/1000 -> 32.67264 | I25: =K25/F25 -> 0.25 | J25: =K25/H25 -> 757.57576 | K25: 24752 | L25: 29702.4 | M25: 20122.78 | N25: 2823.08 | O25: 575.92 | P25: =SUM(M25:O25) -> 23521.78 | Q25: =P25/F25 -> 0.23757454 | R25: =P25/H25 -> 719.92285 | S25: =K25-P25 -> 1230.22 | T25: =S25/P25 -> 0.052301314 | U25: =S25/K25 -> 0.049701842
A26: Bottle 139-КНд | B26: 0.5 | C26: Colored | D26: Belarus | E26: pcs | F26: 466752 | G26: 0.37 | H26: =F26*G26/1000 -> 172.69824 | I26: =K26/F26 -> 0.28 | J26: =K26/H26 -> 756.75676 | K26: 130690.56 | L26: 156828.65 | M26: 104799.61 | N26: 14922.05 | O26: 3044.14 | P26: =SUM(M26:O26) -> 122765.8 | Q26: =P26/F26 -> 0.26302148 | R26: =P26/H26 -> 710.86885 | S26: =K26-P26 -> 7924.76 | T26: =S26/P26 -> 0.064551854 | U26: =S26/K26 -> 0.060637585
... A42: Bottle 103-ВВК | B42: 0.7 | C42: Colored | D42: Belarus | E42: pcs | F42: 31140 | G42: 0.5 | H42: =F42*G42/1000 -> 15.57 | I42: =K42/F42 -> 0.41 | J42: =K42/H42 -> 820 | K42: 12767.4 | L42: 15320.88 | M42: 10269.26 | N42: 1345.33 | O42: 274.45 | P42: =SUM(M42:O42) -> 11889.04 | Q42: =P42/F42 -> 0.38179319 | R42: =P42/H42 -> 763.58638 | S42: =K42-P42 -> 878.36 | T42: =S42/P42 -> 0.073879809 | U42: =S42/K42 -> 0.068797093

Sheet Raw Data
A1: Product | B1: Container Volume (L) | C1: Glass Color | D1: Sales Country | E1: Unit of Measure | F1: Quantity Sold | G1: Unit Weight (kg) | H1: Total Weight (tons) | I1: Average Selling Price per Unit (USD) | J1: Average Selling Price per Ton (USD) | K1: Net Revenue, excl. VAT (USD) | L1: Gross Revenue, incl. VAT (USD) | M1: Manufacturing Cost (USD) | N1: Administrative Expenses (USD) | O1: Selling Expenses (USD) | P1: Total Cost (USD) | Q1: Unit Cost (USD) | R1: Cost per Ton (USD) | S1: Operating Profit (USD) | T1: Product Profitability (%) | U1: Profit Margin (%)
A2: Bottle 32-П-29-А-700 | B2: 0.7 | C2: Color ed | D2: Azerbaijan | E2: pcs | F2: 34560 | G2: 0.45 | H2: 15.552 | I2: 0.12430067 | J2: 276.2237 | K2: 4295.831 | L2: 4295.831 | M2: 3310.2 | N2: 463.36897 | O2: 94.527586 | P2: 3868.0966 | Q2: 0.11192409 | R2: 248.7202 | S2: 427.73448 | T2: 0.11058009 | U2: 0.099569671 | W2: USD | X2: 2.9
A3: Bottle 123-КПШ | B3: 0.75 | C3: Clear | D3: Lithuania | E3: pcs | F3: 163800 | G3: 0.7 | H3: 114.66 | I3: 0.2164876 | J3: 309.268 | K3: 35460.669 | L3: 35460.669 | M3: 28085.8 | N3: 3416.2897 | O3: 696.93448 | P3: 32199.024 | Q3: 0.19657524 | R3: 280.82177 | S3: 3261.6448 | T3: 0.10129639
A4: Bottle 11-ВКП-2 | B4: 0.5 | C4: Colored | D4: Russia | E4: pcs | F4: 152364 | G4: 0.33 | H4: 50.28012 | I4: 0.087931034 | J4: 266.45768 | K4: 13397.524 | L4: 13397.524 | M4: 11977.558 | N4: 1616.9703 | O4: 359.32673 | P4: 13953.855 | Q4: 0.09158236 | R4: 277.5223 | S4: -556.3306 | T4: -0.039869313
A5: Bottle 32-П-29-А-700 | B5: 0.7 | C5: Colored | D5: Russia | E5: pcs | F5: 256980 | G5: 0.45 | H5: 115.641 | J5: 275.86207 | K5: 31900.966 | L5: 31900.966 | M5: 24613.853 | N5: 3322.8702 | O5: 738.4156 | P5: 28675.139 | Q5: 0.1115851 | R5: 247.96689 | S5: 3225.8262 | T5: 0.11249557 | U5: 0.10112002
A6: Bottle 42-КПШ | B6: 0.3 75 | C6: Colored | D6: Russia | E6: pcs | F6: 25630 | G6: 0.457 | H6: 11.71291 | I6: 0.14137931 | J6: 309.36392 | K6: 3623.5517 | L6: 3623.5517 | M6: 2479.4665 | N6: 334.72798 | O6: 74.383996 | P6: 2888.5785 | Q6: 0.11270302 | R6: 246.61493 | S6: 734.97321 | T6: 0.25444114 | U6: 0.20283227
A7: Bottle 138-КПНн | B7: 0.5 68 | C7: Colored | D7: Russia | E7: pcs | F7: 24960 | G7: 0.37 | H7: 9.2352 | I7: 0.094484969 | J7: 255.36478 | K7: 2358.3448 | L7: 2358.3448 | M7: 2110.8946 | N7: 284.97077 | O7: 63.326838 | P7: 2459.1922 | Q7: 0.098525328 | R7: 266.28467 | S7: -100.84737 | T7: -0.041008331 | U7: -0.042761926
A8: Bottle 109-А | B8: 0.5 | C8: Clear | D8: Russia | E8: pcs | F8: 28900 | G8: 0.35 | H8: 10.115 | I8: 0.10344828 | J8: 295.5665 | K8: 2989.6552 | L8: 2989.6552 | M8: 2453.2718 | N8: 331.19169 | O8: 73.598153 | P8: 2858.0616 | Q8: 0.098894866 | R8: 282.55676 | S8: 131.59356 | T8: 0.046042939 | U8: 0.044016299
A9: Bottle 111-В | B9: 0.5 | C9: Colored | D9: Poland | E9: pcs | F9: 156000 | G9: 0.53 | H9: 82.68 | I9: 0.12758621 | J9: 240.72869 | K9: 19903.448 | L9: 19903.448 | M9: 17665.464 | N9: 2384.8376 | O9: 529.96391 | P9: 20580.265 | Q9: 0.13192478 | R9: 248.91467 | S9: -676.81682 | U9: -0.034005003
A10: Bottle 115-КП∞Нб | B10: 0.5 | C10: Colored | D10: Poland | E10: pcs | F10: 483500 | G10: 0.345 | H10: 166.8075 | I10: 0.089655172 | J10: 259.87006 | K10: 43348.276 | L10: 43348.276 | M10: 34629.275 | N10: 4674.9521 | O10: 1038.8782 | P10: 40343.105 | Q10: 0.08343972 | R10: 241.85426 | S10: 3005.171 | T10: 0.074490326 | U10: 0.069326195
A11: Bottle 118-ВВК | B11: 0.5 | C11: Clear | D11: Poland | E11: pcs | F11: 259320 | G11: 0.51 | H11: 132.2532 | J11: 243.40771 | K11: 32191.448 | L11: 32191.448 | M11: 30285.66 | N11: 4088.5642 | O11: 908.56981 | P11: 35282.794 | Q11: 0.1360589 | R11: 266.78216 | S11: -3091.3461 | T11: -0.087616248 | U11: -0.09603004
A12: Bottle 125-В | B12: 0.5 | C12: Clear | D12: Poland | F12: 763980 | G12: 0.415 | H12: 317.0517 | I12: 0.12068966 | J12: 290.81845 | K12: 92204.483 | L12: 92204.483 | M12: 74879.803 | N12: 10108.773 | O12: 2246.3941 | P12: 87234.97 | Q12: 0.11418489 | R12: 275.14431 | S12: 4969.5125 | T12: 0.056966977 | U12: 0.053896648
A13: Bottle 126-В | B13: 0.5 | C13: Clear | D13: Latvia | F13: 85620 | G13: 0.445 | H13: 38.1009 | I13: 0.12931034 | J13: 290.58504 | K13: 11071.552 | L13: 11071.552 | M13: 9875.8455 | N13: 1333.2391 | O13: 296.27537 | P13: 11505.36 | Q13: 0.13437701 | R13: 301.97082 | S13: -433.80829 | T13: -0.037704886 | U13: -0.039182248
A14: Bottle 128-КПН-М | B14: 0.5 | C14: Col ored | D14: Latvia | E14: pcs | F14: 256300 | G14: 0.33 | H14: 84.579 | I14: 0.087931034 | J14: 266.45768 | K14: 22536.724 | L14: 22536.724 | M14: 17962.563 | N14: 2424.946 | O14: 538.87688 | P14: 20926.386 | Q14: 0.081648013 | R14: 247.41822 | S14: 1610.3385 | T14: 0.076952537 | U14: 0.071453972
A15: Bottle 11-ВКП-2 | B15: 0.5 | C15: Colored | D15: Belarus | E15: pcs | F15: 46592 | G15: 0.33 | H15: 15.37536 | I15: 0.086206897 | J15: 261.23302 | K15: 4016.5517 | L15: 4819.8621 | M15: 3662.6655 | N15: 458.1069 | O15: 93.455172 | P15: 4214.2276 | Q15: 0.090449596 | R15: 274.08969 | S15: -197.67586 | T15: -0.046906784 | U15: -0.049215316
A16: Bottle 32-П-29-А-700 | B16: 0.7 | C16: Colored | D16: Belarus | E16: pcs | F16: 200160 | G16: 0.45 | H16: 90.072 | I16: 0.12413793 | J16: 275.86207 | K16: 24847.448 | L16: 29816.938 | M16: 19171.566 | N16: 2683.6793 | O16: 547.46897 | P16: 22402.714 | Q16: 0.11192403 | R16: 248.72007 | S16: 2444.7345 | T16: 0.10912671 | U16: 0.09838976
A17: Bottle 42-КПШ | B17: 0.3 75 | C17: Colored | D17: Belarus | E17: pcs | F17: 85008 | G17: 0.457 | H17: 38.848656 | I17: 0.13793103 | J17: 301.81846 | K17: 11725.241 | L17: 14070.29 | M17: 8223.7414 | N17: 1157.4897 | O17: 236.13103 | P17: 9617.3621 | Q17: 0.11313479 | R17: 247.55971 | S17: 2107.8793 | T17: 0.21917437 | U17: 0.17977279
A18: Bottle 138-КПНн∞ | B18: 0.56 8 | C18: Colored | D18: Belarus | E18: pcs | F18: 170816 | G18: 0.37 | I18: 0.093103448 | J18: 251.63094 | K18: 15903.559 | L18: 19084.272 | M18: 14446.097 | N18: 1883.0966 | O18: 384.15517 | P18: 16713.348 | Q18: 0.097844161 | R18: 264.44368 | S18: -809.78966 | T18: -0.048451671 | U18: -0.050918771
A19: Bottle 109-А | B19: 0.5 | C19: Clear | D19: Bela rus | E19: pcs | F19: 107520 | G19: 0.35 | I19: 0.1 | J19: 285.71429 | K19: 10752 | L19: 12902.4 | M19: 9127.1897 | N19: 1121.2379 | O19: 228.73448 | P19: 10477.162 | Q19: 0.097443844 | R19: 278.41098 | S19: 274.83793 | T19: 0.026232097 | U19: 0.025561564
A20: Bottle 111-В | B20: 0.5 | C20: Colored | D20: Belarus | E20: pcs | F20: 140400 | G20: 0.53 | J20: 240.72869 | K20: 17913.103 | L20: 21495.724 | M20: 15898.917 | N20: 2217.1 | O20: 452.28966 | P20: 18568.307 | Q20: 0.1322529 | R20: 249.53377 | S20: -655.20345 | T20: -0.035286117 | U20: -0.036576769
A21: Bottle 115-КПНб | B21: 0.5 | C21: Colored | D21: Belarus | E21: pcs | F21: 480480 | G21: 0.345 | I21: 0.086206897 | J21: 249.87506 | K21: 41420.69 | L21: 49704.828 | M21: 34412.976 | N21: 4938.9655 | O21: 1007.5517 | P21: 40359.493 | Q21: 0.083998279 | R21: 243.47327 | S21: 1061.1966 | T21: 0.026293605 | U21: 0.025619963
A22: Bottle 118-ВВК | B22: 0.5 | C22: Clear | D22: Belarus | E22: pcs | F22: 264992 | G22: 0.51 | I22: 0.12413793 | J22: 243.40771 | K22: 32895.559 | L22: 39474.666 | M22: 30948.086 | N22: 4026.6655 | O22: 821.43793 | P22: 35796.19 | Q22: 0.13508404 | R22: 264.87066 | S22: -2900.631 | T22: -0.081031838 | U22: -0.088176981
A23: Bottle 125-В | B23: 0.5 | C23: Clear | D23: Belarus | E23: pcs | F23: 99680 | G23: 0.415 | J23: 290.81845 | K23: 12030.345 | L23: 14436.414 | M23: 9769.9138 | N23: 1232.5276 | O23: 251.43793 | P23: 11253.879 | Q23: 0.11290007 | R23: 272.04837 | S23: 776.46552 | T23: 0.068995366 | U23: 0.064542249
A24: Bottle 126-В | B24: 0.5 | C24: Clear | D24: Belarus | E24: pcs | F24: 193440 | G24: 0.445 | I24: 0.12758621 | J24: 286.71058 | K24: 24680.276 | L24: 29616.331 | M24: 22312.352 | N24: 2564.7621 | O24: 523.21724 | P24: 25400.331 | Q24: 0.13130858 | R24: 295.07545 | S24: -720.05517 | T24: -0.028348259 | U24: -0.029175329
A25: Bottle 128-КПН-М | B25: 0.5 | C25: Color ed | D25: Belarus | E25: pcs | F25: 99008 | G25: 0.33 | I25: 0.086206897 | J25: 261.23302 | K25: 8535.1724 | L25: 10242.207 | M25: 6938.8897 | N25: 973.47586 | O25: 198.5931 | P25: 8110.9586 | Q25: 0.081922255 | R25: 248.24926 | S25: 424.21379 | T25: 0.052301314 | U25: 0.049701842
A26: Bottle 139-КНд | B26: 0.5 | C26: C olored | D26: Belarus | E26: pcs | F26: 466752 | G26: 0.37 | I26: 0.096551724 | J26: 260.95061 | K26: 45065.71 | L26: 54078.845 | M26: 36137.797 | N26: 5145.5345 | O26: 1049.7034 | P26: 42333.034 | Q26: 0.090697061 | R26: 245.12719 | S26: 2732.6759 | U26: 0.060637585
A27: Bottle 140-КПМ | B27: 0.5 | C27: Clear | D27: Belarus | F27: 117936 | G27: 0.465 | I27: 0.13793103 | J27: 296.62588 | K27: 16267.034 | L27: 19520.441 | M27: 12563.307 | N27: 1633.9552 | O27: 333.33103 | P27: 14530.593 | Q27: 0.12320744 | R27: 264.96224 | S27: 1736.4414 | T27: 0.11950244 | U27: 0.10674603
A28: Bottle 17-В | B28: 0.5 | C28: Clear | D28: Belarus | E28: pcs | F28: 158536 | G28: 0.347 | H28: 55.011992 | I28: 0.096551724 | J28: 278.24704 | K28: 15306.924 | L28: 18368.31 | M28: 13295.679 | N28: 1639.0828 | O28: 334.37241 | P28: 15269.134 | Q28: 0.096313358 | R28: 277.56011 | S28: 37.789655 | T28: 0.0024749049 | U28: 0.0024687948
A29: Bottle 81-КПМ | B29: 0.5 | C29: Clear | D29: Belarus | E29: pcs | F29: 119340 | G29: 0.425 | H29: 50.7195 | I29: 0.1137931 | J29: 267.74848 | K29: 13580.069 | L29: 16296.083 | M29: 12568.541 | N29: 1511.1828 | O29: 308.28621 | P29: 14388.01 | Q29: 0.12056318 | R29: 283.67808 | S29: -807.94138 | T29: -0.056153795 | U29: -0.059494645
A30: Bottle 110-∞Ш | B30: 0.75 | C30: Clear | D30: Belarus | E30: pcs | F30: 29204 | G30: 0.63 | H30: 18.39852 | I30: 0.17931034 | J30: 284.61959 | K30: 5236.5793 | L30: 6283.8966 | M30: 4421.0414 | N30: 548.18276 | O30: 111.82759 | P30: 5081.0517 | Q30: 0.17398479 | R30: 276.16633 | S30: 155.52759 | T30: 0.030609329 | U30: 0.029700225
A31: Bottle 110-Ш-Green | B31: 0.75 | C31: Colored | D31: Belarus | E31: pcs | F31: 1259104 | G31: 0.63 | H31: 793.23552 | J31: 268.19923 | K31: 212745.16 | L31: 255294.24 | M31: 157933.05 | N31: 23634.366 | O31: 4821.369 | P31: 186388.78 | Q31: 0.14803287 | R31: 234.97281 | S31: 26356.376 | T31: 0.14140538 | U31: 0.12388708
A32: Bottle 110-Ш-Brown | B32: 0.75 | C32: Colored | D32: Belaru s | E32: pcs | F32: 520772 | G32: 0.63 | H32: 328.08636 | I32: 0.16896552 | J32: 268.19923 | K32: 87992.51 | L32: 105591.03 | M32: 66153.034 | N32: 9775.3034 | O32: 1994.1448 | P32: 77922.483 | Q32: 0.14962879 | R32: 237.50601 | S32: 10070.028 | T32: 0.12923135 | U32: 0.11444187
A33: Bottle 117-П | B33: 0.75 | C33: Colored | D33: Belarus | E33: pcs | F33: 105840 | G33: 0.575 | H33: 60.858 | J33: 257.87106 | K33: 15693.517 | L33: 18832.224 | M33: 12411.034 | N33: 1813.2621 | O33: 369.9069 | P33: 14594.203 | Q33: 0.1378893 | R33: 239.80748 | S33: 1099.3138 | T33: 0.075325371 | U33: 0.070048911
A34: Bottle 123-КП∞Ш | B34: 0.75 | C34: Clear | D34: Belarus | E34: pcs | F34: 304200 | G34: 0.7 | H34: 212.94 | I34: 0.19655172 | J34: 280.78818 | K34: 59791.034 | L34: 71749.241 | M34: 52159.348 | N34: 6344.5379 | O34: 1294.3069 | P34: 59798.193 | Q34: 0.19657526 | R34: 280.8218 | S34: -7.1586207 | T34: -0.00011971299 | U34: -0.00011972733
A35: Bottle 12 3-КПШ | B35: 0.75 | C35: Colored | D35: Belarus | E35: pcs | F35: 82800 | G35: 0.7 | H35: 57.96 | I35: 0.19655172 | J35: 280.78818 | K35: 16274.483 | L35: 19529.379 | M35: 11945.603 | N35: 1726.9172 | O35: 352.2931 | P35: 14024.814 | Q35: 0.16938181 | R35: 241.97401 | S35: 2249.669 | T35: 0.16040633
A36: Bottle 31-П-29-Б | B36: 0.75 | C36: Colored | D36: Belarus | F36: 17550 | G36: 0.472 | H36: 8.2836 | I36: 0.12758621 | J36: 270.30976 | K36: 2239.1379 | L36: 2686.9655 | M36: 1822.8069 | N36: 246.81034 | O36: 50.348276 | P36: 2119.9655 | Q36: 0.12079576 | R36: 255.92321 | S36: 119.17241 | T36: 0.056214317
A37: Bottle 32-П-29-А-700 | B37: 0.7 | C37: Clear | D37: Belar us | E37: pcs | F37: 74880 | G37: 0.45 | H37: 33.696 | J37: 275.86207 | K37: 9295.4483 | L37: 11154.538 | M37: 7953.5724 | N37: 1003.9655 | O37: 204.8069 | P37: 9162.3448 | Q37: 0.12236037 | R37: 271.91194 | S37: 133.10345 | T37: 0.014527225
A38: Bottle 127-П-29-Б-700 | B38: 0.7 | C38: Colored | D38: Belarus | E38: pcs | F38: 146250 | G38: 0.58 | H38: 84.825 | J38: 255.64804 | K38: 21685.345 | L38: 26022.414 | M38: 16832.845 | N38: 2527.3448 | O38: 515.58621 | P38: 19875.776 | Q38: 0.13590274 | R38: 234.31507 | S38: 1809.569 | T38: 0.091043941
A39: Bottle 29-В-1 | B39: 0.7 | C39: Clear | D39: Belarus | E39: pcs | F39: 135373 | G39: 0.438 | H39: 59.293374 | J39: 251.92883 | K39: 14937.71 | L39: 17925.252 | M39: 13303.797 | N39: 1766.6414 | O39: 360.3931 | P39: 15430.831 | Q39: 0.11398751 | R39: 260.24545 | S39: -493.12069 | T39: -0.031956846
A40: Bottle 29-В | B40: 0.7 | C40: Colored | D40: Belarus | E40: pcs | F40: 536599 | G40: 0.438 | H40: 235.03036 | I40: 0.11034483 | J40: 251.92883 | K40: 59210.924 | L40: 71053.1 | M40: 45073 | N40: 7002.7 | O40: 1428.5621 | P40: 53504.262 | Q40: 0.099709955 | R40: 227.6483 | S40: 5706.6621 | T40: 0.10665808 | U40: 0.096378534
...

Sheet Clean Data
A1: Product | B1: Container Volume (L) | C1: Glass Color | D1: Sales Country | E1: Unit of Measure | F1: Quantity Sold | G1: Unit Weight (kg) | H1: Total Weight (tons) | I1: Average Selling Price per Unit (USD) | J1: Average Selling Price per Ton (USD) | K1: Net Revenue, excl. VAT (USD) | L1: Gross Revenue, incl. VAT (USD) | M1: Manufacturing Cost (USD) | N1: Administrative Expenses (USD) | O1: Selling Expenses (USD) | P1: Total Cost (USD) | Q1: Unit Cost (USD) | R1: Cost per Ton (USD) | S1: Operating Profit (USD) | T1: Product Profitability (%) | U1: Profit Margin (%)
A2: Bottle 32-П-29-А-700 | B2: =SUBSTITUTE(TRIM(CLEAN('Raw Data'!B2))," ","") -> 0.7 | C2: =SUBSTITUTE(TRIM(CLEAN('Raw Data'!C2))," ","") -> Colored | D2: =SUBSTITUTE(TRIM(CLEAN('Raw Data'!D2))," ","") -> Azerbaijan | E2: ='Raw Data'!E2 -> pcs | F2: ='Raw Data'!F2 -> 34560 | G2: ='Raw Data'!G2 -> 0.45 | H2: =IF(ISBLANK('Raw Data'!H2),Table3[[#This Row],[Quantity Sold]]*Table3[[#This Row],[Unit Weight (kg)]]/1000,Table2[[#This Row],[Total Weight (tons)]]) -> 15.552 | I2: =IF(ISBLANK('Raw Data'!I2),Table3[[#This Row],[Net Revenue, excl. VAT (USD)]]/Table3[[#This Row],[Quantity Sold]],Table2[[#This Row],[Average Selling Price per Unit (USD)]]) -> 0.12430067 | J2: ='Raw Data'!J2 -> 276.2237 | K2: ='Raw Data'!K2 -> 4295.831 | L2: ='Raw Data'!L2 -> 4295.831 | M2: ='Raw Data'!M2 -> 3310.2 | N2: ='Raw Data'!N2 -> 463.36897 | O2: ='Raw Data'!O2 -> 94.527586 | P2: ='Raw Data'!P2 -> 3868.0966 | Q2: ='Raw Data'!Q2 -> 0.11192409 | ... S2: ='Raw Data'!S2 -> 427.73448 | T2: =IF(ISBLANK('Raw Data'!T2),Table3[[#This Row],[Operating Profit (USD)]]/Table3[[#This Row],[Total Cost (USD)]],Table2[[#This Row],[Product Profitability (%)]]) -> 0.11058009 | U2: =IF(ISBLANK('Raw Data'!U2),Table3[[#This Row],[Operating Profit (USD)]]/Table3[[#This Row],[Net Revenue, excl. VAT (USD)]],Table2[[#This Row],[Profit Margin (%)]]) -> 0.099569671
A3: Bottle 123-КПШ | B3: =SUBSTITUTE(TRIM(CLEAN('Raw Data'!B3))," ","") -> 0.75 | C3: =SUBSTITUTE(TRIM(CLEAN('Raw Data'!C3))," ","") -> Clear | D3: =SUBSTITUTE(TRIM(CLEAN('Raw Data'!D3))," ","") -> Lithuania | E3: =IF(ISBLANK('Raw Data'!E3),E2,Table2[[#This Row],[Unit of Measure]]) -> pcs | F3: ='Raw Data'!F3 -> 163800 | G3: ='Raw Data'!G3 -> 0.7 | H3: =IF(ISBLANK('Raw Data'!H3),Table3[[#This Row],[Quantity Sold]]*Table3[[#This Row],[Unit Weight (kg)]]/1000,Table2[[#This Row],[Total Weight (tons)]]) -> 114.66 | I3: =IF(ISBLANK('Raw Data'!I3),Table3[[#This Row],[Net Revenue, excl. VAT (USD)]]/Table3[[#This Row],[Quantity Sold]],Table2[[#This Row],[Average Selling Price per Unit (USD)]]) -> 0.2164876 | J3: ='Raw Data'!J3 -> 309.268 | K3: ='Raw Data'!K3 -> 35460.669 | L3: ='Raw Data'!L3 -> 35460.669 | M3: ='Raw Data'!M3 -> 28085.8 | N3: ='Raw Data'!N3 -> 3416.2897 | O3: ='Raw Data'!O3 -> 696.93448 | P3: ='Raw Data'!P3 -> 32199.024 | Q3: ='Raw Data'!Q3 -> 0.19657524 | ... S3: ='Raw Data'!S3 -> 3261.6448 | T3: =IF(ISBLANK('Raw Data'!T3),Table3[[#This Row],[Operating Profit (USD)]]/Table3[[#This Row],[Total Cost (USD)]],Table2[[#This Row],[Product Profitability (%)]]) -> 0.10129639 | U3: =IF(ISBLANK('Raw Data'!U3),Table3[[#This Row],[Operating Profit (USD)]]/Table3[[#This Row],[Net Revenue, excl. VAT (USD)]],Table2[[#This Row],[Profit Margin (%)]]) -> 0.091979224
A4: Bottle 11-ВКП-2 | B4: =SUBSTITUTE(TRIM(CLEAN('Raw Data'!B4))," ","") -> 0.5 | C4: =SUBSTITUTE(TRIM(CLEAN('Raw Data'!C4))," ","") -> Colored | D4: =SUBSTITUTE(TRIM(CLEAN('Raw Data'!D4))," ","") -> Russia | E4: =IF(ISBLANK('Raw Data'!E4),E3,Table2[[#This Row],[Unit of Measure]]) -> pcs | F4: ='Raw Data'!F4 -> 152364 | G4: ='Raw Data'!G4 -> 0.33 | H4: =IF(ISBLANK('Raw Data'!H4),Table3[[#This Row],[Quantity Sold]]*Table3[[#This Row],[Unit Weight (kg)]]/1000,Table2[[#This Row],[Total Weight (tons)]]) -> 50.28012 | I4: =IF(ISBLANK('Raw Data'!I4),Table3[[#This Row],[Net Revenue, excl. VAT (USD)]]/Table3[[#This Row],[Quantity Sold]],Table2[[#This Row],[Average Selling Price per Unit (USD)]]) -> 0.087931034 | J4: ='Raw Data'!J4 -> 266.45768 | K4: ='Raw Data'!K4 -> 13397.524 | L4: ='Raw Data'!L4 -> 13397.524 | M4: ='Raw Data'!M4 -> 11977.558 | N4: ='Raw Data'!N4 -> 1616.9703 | O4: ='Raw Data'!O4 -> 359.32673 | P4: ='Raw Data'!P4 -> 13953.855 | Q4: ='Raw Data'!Q4 -> 0.09158236 | ... S4: ='Raw Data'!S4 -> -556.3306 | T4: =IF(ISBLANK('Raw Data'!T4),Table3[[#This Row],[Operating Profit (USD)]]/Table3[[#This Row],[Total Cost (USD)]],Table2[[#This Row],[Product Profitability (%)]]) -> -0.039869313 | U4: =IF(ISBLANK('Raw Data'!U4),Table3[[#This Row],[Operating Profit (USD)]]/Table3[[#This Row],[Net Revenue, excl. VAT (USD)]],Table2[[#This Row],[Profit Margin (%)]]) -> -0.041524881
A5: Bottle 32-П-29-А-700 | B5: =SUBSTITUTE(TRIM(CLEAN('Raw Data'!B5))," ","") -> 0.7 | C5: =SUBSTITUTE(TRIM(CLEAN('Raw Data'!C5))," ","") -> Colored | D5: =SUBSTITUTE(TRIM(CLEAN('Raw Data'!D5))," ","") -> Russia | E5: =IF(ISBLANK('Raw Data'!E5),E4,Table2[[#This Row],[Unit of Measure]]) -> pcs | F5: ='Raw Data'!F5 -> 256980 | G5: ='Raw Data'!G5 -> 0.45 | H5: =IF(ISBLANK('Raw Data'!H5),Table3[[#This Row],[Quantity Sold]]*Table3[[#This Row],[Unit Weight (kg)]]/1000,Table2[[#This Row],[Total Weight (tons)]]) -> 115.641 | I5: =IF(ISBLANK('Raw Data'!I5),Table3[[#This Row],[Net Revenue, excl. VAT (USD)]]/Table3[[#This Row],[Quantity Sold]],Table2[[#This Row],[Average Selling Price per Unit (USD)]]) -> 0.12413793 | J5: ='Raw Data'!J5 -> 275.86207 | K5: ='Raw Data'!K5 -> 31900.966 | L5: ='Raw Data'!L5 -> 31900.966 | M5: ='Raw Data'!M5 -> 24613.853 | N5: ='Raw Data'!N5 -> 3322.8702 | O5: ='Raw Data'!O5 -> 738.4156 | P5: ='Raw Data'!P5 -> 28675.139 | Q5: ='Raw Data'!Q5 -> 0.1115851 | ... S5: ='Raw Data'!S5 -> 3225.8262 | T5: =IF(ISBLANK('Raw Data'!T5),Table3[[#This Row],[Operating Profit (USD)]]/Table3[[#This Row],[Total Cost (USD)]],Table2[[#This Row],[Product Profitability (%)]]) -> 0.11249557 | U5: =IF(ISBLANK('Raw Data'!U5),Table3[[#This Row],[Operating Profit (USD)]]/Table3[[#This Row],[Net Revenue, excl. VAT (USD)]],Table2[[#This Row],[Profit Margin (%)]]) -> 0.10112002
A6: Bottle 42-КПШ | B6: =SUBSTITUTE(TRIM(CLEAN('Raw Data'!B6))," ","") -> 0.375 | C6: =SUBSTITUTE(TRIM(CLEAN('Raw Data'!C6))," ","") -> Colored | D6: =SUBSTITUTE(TRIM(CLEAN('Raw Data'!D6))," ","") -> Russia | E6: =IF(ISBLANK('Raw Data'!E6),E5,Table2[[#This Row],[Unit of Measure]]) -> pcs | F6: ='Raw Data'!F6 -> 25630 | G6: ='Raw Data'!G6 -> 0.457 | H6: =IF(ISBLANK('Raw Data'!H6),Table3[[#This Row],[Quantity Sold]]*Table3[[#This Row],[Unit Weight (kg)]]/1000,Table2[[#This Row],[Total Weight (tons)]]) -> 11.71291 | I6: =IF(ISBLANK('Raw Data'!I6),Table3[[#This Row],[Net Revenue, excl. VAT (USD)]]/Table3[[#This Row],[Quantity Sold]],Table2[[#This Row],[Average Selling Price per Unit (USD)]]) -> 0.14137931 | J6: ='Raw Data'!J6 -> 309.36392 | K6: ='Raw Data'!K6 -> 3623.5517 | L6: ='Raw Data'!L6 -> 3623.5517 | M6: ='Raw Data'!M6 -> 2479.4665 | N6: ='Raw Data'!N6 -> 334.72798 | O6: ='Raw Data'!O6 -> 74.383996 | P6: ='Raw Data'!P6 -> 2888.5785 | Q6: ='Raw Data'!Q6 -> 0.11270302 | ... S6: ='Raw Data'!S6 -> 734.97321 | T6: =IF(ISBLANK('Raw Data'!T6),Table3[[#This Row],[Operating Profit (USD)]]/Table3[[#This Row],[Total Cost (USD)]],Table2[[#This Row],[Product Profitability (%)]]) -> 0.25444114 | U6: =IF(ISBLANK('Raw Data'!U6),Table3[[#This Row],[Operating Profit (USD)]]/Table3[[#This Row],[Net Revenue, excl. VAT (USD)]],Table2[[#This Row],[Profit Margin (%)]]) -> 0.20283227
A7: Bottle 138-КПНн | B7: =SUBSTITUTE(TRIM(CLEAN('Raw Data'!B7))," ","") -> 0.568 | C7: =SUBSTITUTE(TRIM(CLEAN('Raw Data'!C7))," ","") -> Colored | D7: =SUBSTITUTE(TRIM(CLEAN('Raw Data'!D7))," ","") -> Russia | E7: =IF(ISBLANK('Raw Data'!E7),E6,Table2[[#This Row],[Unit of Measure]]) -> pcs | F7: ='Raw Data'!F7 -> 24960 | G7: ='Raw Data'!G7 -> 0.37 | H7: =IF(ISBLANK('Raw Data'!H7),Table3[[#This Row],[Quantity Sold]]*Table3[[#This Row],[Unit Weight (kg)]]/1000,Table2[[#This Row],[Total Weight (tons)]]) -> 9.2352 | I7: =IF(ISBLANK('Raw Data'!I7),Table3[[#This Row],[Net Revenue, excl. VAT (USD)]]/Table3[[#This Row],[Quantity Sold]],Table2[[#This Row],[Average Selling Price per Unit (USD)]]) -> 0.094484969 | J7: ='Raw Data'!J7 -> 255.36478 | K7: ='Raw Data'!K7 -> 2358.3448 | L7: ='Raw Data'!L7 -> 2358.3448 | M7: ='Raw Data'!M7 -> 2110.8946 | N7: ='Raw Data'!N7 -> 284.97077 | O7: ='Raw Data'!O7 -> 63.326838 | P7: ='Raw Data'!P7 -> 2459.1922 | Q7: ='Raw Data'!Q7 -> 0.098525328 | ... S7: ='Raw Data'!S7 -> -100.84737 | T7: =IF(ISBLANK('Raw Data'!T7),Table3[[#This Row],[Operating Profit (USD)]]/Table3[[#This Row],[Total Cost (USD)]],Table2[[#This Row],[Product Profitability (%)]]) -> -0.041008331 | U7: =IF(ISBLANK('Raw Data'!U7),Table3[[#This Row],[Operating Profit (USD)]]/Table3[[#This Row],[Net Revenue, excl. VAT (USD)]],Table2[[#This Row],[Profit Margin (%)]]) -> -0.042761926
A8: Bottle 109-А | B8: =SUBSTITUTE(TRIM(CLEAN('Raw Data'!B8))," ","") -> 0.5 | C8: =SUBSTITUTE(TRIM(CLEAN('Raw Data'!C8))," ","") -> Clear | D8: =SUBSTITUTE(TRIM(CLEAN('Raw Data'!D8))," ","") -> Russia | E8: =IF(ISBLANK('Raw Data'!E8),E7,Table2[[#This Row],[Unit of Measure]]) -> pcs | F8: ='Raw Data'!F8 -> 28900 | G8: ='Raw Data'!G8 -> 0.35 | H8: =IF(ISBLANK('Raw Data'!H8),Table3[[#This Row],[Quantity Sold]]*Table3[[#This Row],[Unit Weight (kg)]]/1000,Table2[[#This Row],[Total Weight (tons)]]) -> 10.115 | I8: =IF(ISBLANK('Raw Data'!I8),Table3[[#This Row],[Net Revenue, excl. VAT (USD)]]/Table3[[#This Row],[Quantity Sold]],Table2[[#This Row],[Average Selling Price per Unit (USD)]]) -> 0.10344828 | J8: ='Raw Data'!J8 -> 295.5665 | K8: ='Raw Data'!K8 -> 2989.6552 | L8: ='Raw Data'!L8 -> 2989.6552 | M8: ='Raw Data'!M8 -> 2453.2718 | N8: ='Raw Data'!N8 -> 331.19169 | O8: ='Raw Data'!O8 -> 73.598153 | P8: ='Raw Data'!P8 -> 2858.0616 | Q8: ='Raw Data'!Q8 -> 0.098894866 | ... S8: ='Raw Data'!S8 -> 131.59356 | T8: =IF(ISBLANK('Raw Data'!T8),Table3[[#This Row],[Operating Profit (USD)]]/Table3[[#This Row],[Total Cost (USD)]],Table2[[#This Row],[Product Profitability (%)]]) -> 0.046042939 | U8: =IF(ISBLANK('Raw Data'!U8),Table3[[#This Row],[Operating Profit (USD)]]/Table3[[#This Row],[Net Revenue, excl. VAT (USD)]],Table2[[#This Row],[Profit Margin (%)]]) -> 0.044016299
A9: Bottle 111-В | B9: =SUBSTITUTE(TRIM(CLEAN('Raw Data'!B9))," ","") -> 0.5 | C9: =SUBSTITUTE(TRIM(CLEAN('Raw Data'!C9))," ","") -> Colored | D9: =SUBSTITUTE(TRIM(CLEAN('Raw Data'!D9))," ","") -> Poland | E9: =IF(ISBLANK('Raw Data'!E9),E8,Table2[[#This Row],[Unit of Measure]]) -> pcs | F9: ='Raw Data'!F9 -> 156000 | G9: ='Raw Data'!G9 -> 0.53 | H9: =IF(ISBLANK('Raw Data'!H9),Table3[[#This Row],[Quantity Sold]]*Table3[[#This Row],[Unit Weight (kg)]]/1000,Table2[[#This Row],[Total Weight (tons)]]) -> 82.68 | I9: =IF(ISBLANK('Raw Data'!I9),Table3[[#This Row],[Net Revenue, excl. VAT (USD)]]/Table3[[#This Row],[Quantity Sold]],Table2[[#This Row],[Average Selling Price per Unit (USD)]]) -> 0.12758621 | J9: ='Raw Data'!J9 -> 240.72869 | K9: ='Raw Data'!K9 -> 19903.448 | L9: ='Raw Data'!L9 -> 19903.448 | M9: ='Raw Data'!M9 -> 17665.464 | N9: ='Raw Data'!N9 -> 2384.8376 | O9: ='Raw Data'!O9 -> 529.96391 | P9: ='Raw Data'!P9 -> 20580.265 | Q9: ='Raw Data'!Q9 -> 0.13192478 | ... S9: ='Raw Data'!S9 -> -676.81682 | T9: =IF(ISBLANK('Raw Data'!T9),Table3[[#This Row],[Operating Profit (USD)]]/Table3[[#This Row],[Total Cost (USD)]],Table2[[#This Row],[Product Profitability (%)]]) -> -0.032886691 | U9: =IF(ISBLANK('Raw Data'!U9),Table3[[#This Row],[Operating Profit (USD)]]/Table3[[#This Row],[Net Revenue, excl. VAT (USD)]],Table2[[#This Row],[Profit Margin (%)]]) -> -0.034005003
A10: Bottle 115-КПНб | B10: =SUBSTITUTE(TRIM(CLEAN('Raw Data'!B10))," ","") -> 0.5 | C10: =SUBSTITUTE(TRIM(CLEAN('Raw Data'!C10))," ","") -> Colored | D10: =SUBSTITUTE(TRIM(CLEAN('Raw Data'!D10))," ","") -> Poland | E10: =IF(ISBLANK('Raw Data'!E10),E9,Table2[[#This Row],[Unit of Measure]]) -> pcs | F10: ='Raw Data'!F10 -> 483500 | G10: ='Raw Data'!G10 -> 0.345 | H10: =IF(ISBLANK('Raw Data'!H10),Table3[[#This Row],[Quantity Sold]]*Table3[[#This Row],[Unit Weight (kg)]]/1000,Table2[[#This Row],[Total Weight (tons)]]) -> 166.8075 | I10: =IF(ISBLANK('Raw Data'!I10),Table3[[#This Row],[Net Revenue, excl. VAT (USD)]]/Table3[[#This Row],[Quantity Sold]],Table2[[#This Row],[Average Selling Price per Unit (USD)]]) -> 0.089655172 | J10: ='Raw Data'!J10 -> 259.87006 | K10: ='Raw Data'!K10 -> 43348.276 | L10: ='Raw Data'!L10 -> 43348.276 | M10: ='Raw Data'!M10 -> 34629.275 | N10: ='Raw Data'!N10 -> 4674.9521 | O10: ='Raw Data'!O10 -> 1038.8782 | P10: ='Raw Data'!P10 -> 40343.105 | Q10: ='Raw Data'!Q10 -> 0.08343972 | ... S10: ='Raw Data'!S10 -> 3005.171 | T10: =IF(ISBLANK('Raw Data'!T10),Table3[[#This Row],[Operating Profit (USD)]]/Table3[[#This Row],[Total Cost (USD)]],Table2[[#This Row],[Product Profitability (%)]]) -> 0.074490326 | U10: =IF(ISBLANK('Raw Data'!U10),Table3[[#This Row],[Operating Profit (USD)]]/Table3[[#This Row],[Net Revenue, excl. VAT (USD)]],Table2[[#This Row],[Profit Margin (%)]]) -> 0.069326195
A11: Bottle 118-ВВК | B11: =SUBSTITUTE(TRIM(CLEAN('Raw Data'!B11))," ","") -> 0.5 | C11: =SUBSTITUTE(TRIM(CLEAN('Raw Data'!C11))," ","") -> Clear | D11: =SUBSTITUTE(TRIM(CLEAN('Raw Data'!D11))," ","") -> Poland | E11: =IF(ISBLANK('Raw Data'!E11),E10,Table2[[#This Row],[Unit of Measure]]) -> pcs | F11: ='Raw Data'!F11 -> 259320 | G11: ='Raw Data'!G11 -> 0.51 | H11: =IF(ISBLANK('Raw Data'!H11),Table3[[#This Row],[Quantity Sold]]*Table3[[#This Row],[Unit Weight (kg)]]/1000,Table2[[#This Row],[Total Weight (tons)]]) -> 132.2532 | I11: =IF(ISBLANK('Raw Data'!I11),Table3[[#This Row],[Net Revenue, excl. VAT (USD)]]/Table3[[#This Row],[Quantity Sold]],Table2[[#This Row],[Average Selling Price per Unit (USD)]]) -> 0.12413793 | J11: ='Raw Data'!J11 -> 243.40771 | K11: ='Raw Data'!K11 -> 32191.448 | L11: ='Raw Data'!L11 -> 32191.448 | M11: ='Raw Data'!M11 -> 30285.66 | N11: ='Raw Data'!N11 -> 4088.5642 | O11: ='Raw Data'!O11 -> 908.56981 | P11: ='Raw Data'!P11 -> 35282.794 | Q11: ='Raw Data'!Q11 -> 0.1360589 | ... S11: ='Raw Data'!S11 -> -3091.3461 | T11: =IF(ISBLANK('Raw Data'!T11),Table3[[#This Row],[Operating Profit (USD)]]/Table3[[#This Row],[Total Cost (USD)]],Table2[[#This Row],[Product Profitability (%)]]) -> -0.087616248 | U11: =IF(ISBLANK('Raw Data'!U11),Table3[[#This Row],[Operating Profit (USD)]]/Table3[[#This Row],[Net Revenue, excl. VAT (USD)]],Table2[[#This Row],[Profit Margin (%)]]) -> -0.09603004
A12: Bottle 125-В | B12: =SUBSTITUTE(TRIM(CLEAN('Raw Data'!B12))," ","") -> 0.5 | C12: =SUBSTITUTE(TRIM(CLEAN('Raw Data'!C12))," ","") -> Clear | D12: =SUBSTITUTE(TRIM(CLEAN('Raw Data'!D12))," ","") -> Poland | E12: =IF(ISBLANK('Raw Data'!E12),E11,Table2[[#This Row],[Unit of Measure]]) -> pcs | F12: ='Raw Data'!F12 -> 763980 | G12: ='Raw Data'!G12 -> 0.415 | H12: =IF(ISBLANK('Raw Data'!H12),Table3[[#This Row],[Quantity Sold]]*Table3[[#This Row],[Unit Weight (kg)]]/1000,Table2[[#This Row],[Total Weight (tons)]]) -> 317.0517 | I12: =IF(ISBLANK('Raw Data'!I12),Table3[[#This Row],[Net Revenue, excl. VAT (USD)]]/Table3[[#This Row],[Quantity Sold]],Table2[[#This Row],[Average Selling Price per Unit (USD)]]) -> 0.12068966 | J12: ='Raw Data'!J12 -> 290.81845 | K12: ='Raw Data'!K12 -> 92204.483 | L12: ='Raw Data'!L12 -> 92204.483 | M12: ='Raw Data'!M12 -> 74879.803 | N12: ='Raw Data'!N12 -> 10108.773 | O12: ='Raw Data'!O12 -> 2246.3941 | P12: ='Raw Data'!P12 -> 87234.97 | Q12: ='Raw Data'!Q12 -> 0.11418489 | ... S12: ='Raw Data'!S12 -> 4969.5125 | T12: =IF(ISBLANK('Raw Data'!T12),Table3[[#This Row],[Operating Profit (USD)]]/Table3[[#This Row],[Total Cost (USD)]],Table2[[#This Row],[Product Profitability (%)]]) -> 0.056966977 | U12: =IF(ISBLANK('Raw Data'!U12),Table3[[#This Row],[Operating Profit (USD)]]/Table3[[#This Row],[Net Revenue, excl. VAT (USD)]],Table2[[#This Row],[Profit Margin (%)]]) -> 0.053896648
A13: Bottle 126-В | B13: =SUBSTITUTE(TRIM(CLEAN('Raw Data'!B13))," ","") -> 0.5 | C13: =SUBSTITUTE(TRIM(CLEAN('Raw Data'!C13))," ","") -> Clear | D13: =SUBSTITUTE(TRIM(CLEAN('Raw Data'!D13))," ","") -> Latvia | E13: =IF(ISBLANK('Raw Data'!E13),E12,Table2[[#This Row],[Unit of Measure]]) -> pcs | F13: ='Raw Data'!F13 -> 85620 | G13: ='Raw Data'!G13 -> 0.445 | H13: =IF(ISBLANK('Raw Data'!H13),Table3[[#This Row],[Quantity Sold]]*Table3[[#This Row],[Unit Weight (kg)]]/1000,Table2[[#This Row],[Total Weight (tons)]]) -> 38.1009 | I13: =IF(ISBLANK('Raw Data'!I13),Table3[[#This Row],[Net Revenue, excl. VAT (USD)]]/Table3[[#This Row],[Quantity Sold]],Table2[[#This Row],[Average Selling Price per Unit (USD)]]) -> 0.12931034 | J13: ='Raw Data'!J13 -> 290.58504 | K13: ='Raw Data'!K13 -> 11071.552 | L13: ='Raw Data'!L13 -> 11071.552 | M13: ='Raw Data'!M13 -> 9875.8455 | N13: ='Raw Data'!N13 -> 1333.2391 | O13: ='Raw Data'!O13 -> 296.27537 | P13: ='Raw Data'!P13 -> 11505.36 | Q13: ='Raw Data'!Q13 -> 0.13437701 | ... S13: ='Raw Data'!S13 -> -433.80829 | T13: =IF(ISBLANK('Raw Data'!T13),Table3[[#This Row],[Operating Profit (USD)]]/Table3[[#This Row],[Total Cost (USD)]],Table2[[#This Row],[Product Profitability (%)]]) -> -0.037704886 | U13: =IF(ISBLANK('Raw Data'!U13),Table3[[#This Row],[Operating Profit (USD)]]/Table3[[#This Row],[Net Revenue, excl. VAT (USD)]],Table2[[#This Row],[Profit Margin (%)]]) -> -0.039182248
A14: Bottle 128-КПН-М | B14: =SUBSTITUTE(TRIM(CLEAN('Raw Data'!B14))," ","") -> 0.5 | C14: =SUBSTITUTE(TRIM(CLEAN('Raw Data'!C14))," ","") -> Colored | D14: =SUBSTITUTE(TRIM(CLEAN('Raw Data'!D14))," ","") -> Latvia | E14: =IF(ISBLANK('Raw Data'!E14),E13,Table2[[#This Row],[Unit of Measure]]) -> pcs | F14: ='Raw Data'!F14 -> 256300 | G14: ='Raw Data'!G14 -> 0.33 | H14: =IF(ISBLANK('Raw Data'!H14),Table3[[#This Row],[Quantity Sold]]*Table3[[#This Row],[Unit Weight (kg)]]/1000,Table2[[#This Row],[Total Weight (tons)]]) -> 84.579 | I14: =IF(ISBLANK('Raw Data'!I14),Table3[[#This Row],[Net Revenue, excl. VAT (USD)]]/Table3[[#This Row],[Quantity Sold]],Table2[[#This Row],[Average Selling Price per Unit (USD)]]) -> 0.087931034 | J14: ='Raw Data'!J14 -> 266.45768 | K14: ='Raw Data'!K14 -> 22536.724 | L14: ='Raw Data'!L14 -> 22536.724 | M14: ='Raw Data'!M14 -> 17962.563 | N14: ='Raw Data'!N14 -> 2424.946 | O14: ='Raw Data'!O14 -> 538.87688 | P14: ='Raw Data'!P14 -> 20926.386 | Q14: ='Raw Data'!Q14 -> 0.081648013 | ... S14: ='Raw Data'!S14 -> 1610.3385 | T14: =IF(ISBLANK('Raw Data'!T14),Table3[[#This Row],[Operating Profit (USD)]]/Table3[[#This Row],[Total Cost (USD)]],Table2[[#This Row],[Product Profitability (%)]]) -> 0.076952537 | U14: =IF(ISBLANK('Raw Data'!U14),Table3[[#This Row],[Operating Profit (USD)]]/Table3[[#This Row],[Net Revenue, excl. VAT (USD)]],Table2[[#This Row],[Profit Margin (%)]]) -> 0.071453972
... A42: Bottle 103-ВВК | B42: =SUBSTITUTE(TRIM(CLEAN('Raw Data'!B42))," ","") -> 0.7 | C42: =SUBSTITUTE(TRIM(CLEAN('Raw Data'!C42))," ","") -> Colored | D42: =SUBSTITUTE(TRIM(CLEAN('Raw Data'!D42))," ","") -> Belarus | E42: =IF(ISBLANK('Raw Data'!E42),E41,Table2[[#This Row],[Unit of Measure]]) -> pcs | F42: ='Raw Data'!F42 -> 31140 | G42: ='Raw Data'!G42 -> 0.5 | H42: =IF(ISBLANK('Raw Data'!H42),Table3[[#This Row],[Quantity Sold]]*Table3[[#This Row],[Unit Weight (kg)]]/1000,Table2[[#This Row],[Total Weight (tons)]]) -> 15.57 | I42: =IF(ISBLANK('Raw Data'!I42),Table3[[#This Row],[Net Revenue, excl. VAT (USD)]]/Table3[[#This Row],[Quantity Sold]],Table2[[#This Row],[Average Selling Price per Unit (USD)]]) -> 0.14137931 | J42: ='Raw Data'!J42 -> 282.75862 | K42: ='Raw Data'!K42 -> 4402.5517 | L42: ='Raw Data'!L42 -> 5283.0621 | M42: ='Raw Data'!M42 -> 3541.1241 | N42: ='Raw Data'!N42 -> 463.9069 | O42: ='Raw Data'!O42 -> 94.637931 | P42: ='Raw Data'!P42 -> 4099.669 | Q42: ='Raw Data'!Q42 -> 0.13165282 | ... S42: ='Raw Data'!S42 -> 302.88276 | T42: =IF(ISBLANK('Raw Data'!T42),Table3[[#This Row],[Operating Profit (USD)]]/Table3[[#This Row],[Total Cost (USD)]],Table2[[#This Row],[Product Profitability (%)]]) -> 0.073879809 | U42: =IF(ISBLANK('Raw Data'!U42),Table3[[#This Row],[Operating Profit (USD)]]/Table3[[#This Row],[Net Revenue, excl. VAT (USD)]],Table2[[#This Row],[Profit Margin (%)]]) -> 0.068797093

Sheet Dashboard
H15: Metrics for | I15: TOP 5 profitable bottles
G16: Product | I16: ='Calcs for dash'!H55 -> Product profitability | J16: ='Calcs for dash'!I55 -> Quantity Sold
G17: =IF($I$15='Calcs for dash'!$G$54,'Calcs for dash'!G56,'Calcs for dash'!G65) -> Bottle 42-КПШ | I17: =IF($I$15='Calcs for dash'!$G$54,'Calcs for dash'!H56,'Calcs for dash'!H65) -> 0.22732017 | J17: =IF($I$15='Calcs for dash'!$G$54,'Calcs for dash'!I56,'Calcs for dash'!I65) -> 110638
G18: =IF($I$15='Calcs for dash'!$G$54,'Calcs for dash'!G57,'Calcs for dash'!G66) -> Bottle 110-Ш-Green | I18: =IF($I$15='Calcs for dash'!$G$54,'Calcs for dash'!H57,'Calcs for dash'!H66) -> 0.14140538 | J18: =IF($I$15='Calcs for dash'!$G$54,'Calcs for dash'!I57,'Calcs for dash'!I66) -> 1259104
G19: =IF($I$15='Calcs for dash'!$G$54,'Calcs for dash'!G58,'Calcs for dash'!G67) -> Bottle 110-Ш-Brown | I19: =IF($I$15='Calcs for dash'!$G$54,'Calcs for dash'!H58,'Calcs for dash'!H67) -> 0.12923135 | J19: =IF($I$15='Calcs for dash'!$G$54,'Calcs for dash'!I58,'Calcs for dash'!I67) -> 520772
G20: =IF($I$15='Calcs for dash'!$G$54,'Calcs for dash'!G59,'Calcs for dash'!G68) -> Bottle 140-КПМ | I20: =IF($I$15='Calcs for dash'!$G$54,'Calcs for dash'!H59,'Calcs for dash'!H68) -> 0.11950244 | J20: =IF($I$15='Calcs for dash'!$G$54,'Calcs for dash'!I59,'Calcs for dash'!I68) -> 117936
G21: =IF($I$15='Calcs for dash'!$G$54,'Calcs for dash'!G60,'Calcs for dash'!G69) -> Bottle 32-П-29-Б | I21: =IF($I$15='Calcs for dash'!$G$54,'Calcs for dash'!H60,'Calcs for dash'!H69) -> 0.11648897 | J21: =IF($I$15='Calcs for dash'!$G$54,'Calcs for dash'!I60,'Calcs for dash'!I69) -> 37440

Sheet Calcs for dash
A2: Average unit weight | B2: =AVERAGE(Table3[Unit Weight (kg)]) -> 0.4637561
A3: Average selling price | B3: =B11/B12 -> 0.12888693
A4: Average unit cost | B4: =B13/B12 -> 0.12132141
A5: Product profitability (month) | B5: =B14/B13 -> 0.062359318
A6: Profit margin (month) | B6: =B14/B11 -> 0.058698895
A10: Summary data
A11: Net Revenue, excl. VAT (USD) | B11: =SUM(Table3[Net Revenue, excl. VAT (USD)]) -> 1124374.3
A12: Quantity Sold | B12: =SUM(Table3[Quantity Sold]) -> 8723726
A13: Total Cost (USD) | B13: =SUM(Table3[Total Cost (USD)]) -> 1058374.8
A14: Operating Profit (USD) | B14: =SUM(Table3[Operating Profit (USD)]) -> 65999.528
A18: Pie chart | B18: Quantity Sold by color
A19: Clear | B19: =SUMIF('Clean Data'!C2:C42,'Clean Data'!C3,Table3[Quantity Sold]) -> 2906721
A20: Colored | B20: =SUMIF('Clean Data'!C2:C42,'Clean Data'!C4,Table3[Quantity Sold]) -> 5817005
A25: Pie chart | B25: Operating Profit by Glass Color(USD)
A26: Clear | B26: =SUMIF(Table3[Glass Color],'Clean Data'!C3,Table3[Operating Profit (USD)]) -> 3022.8552
A27: Colored | B27: =SUMIF(Table3[Glass Color],'Clean Data'!C4,Table3[Operating Profit (USD)]) -> 62976.673
B44: Quantity Sold
A45: Belarus | B45: =SUMIF(Table3[Sales Country],'Calcs for dash'!A45,Table3[Quantity Sold]) -> 6031812
A46: Poland | B46: =SUMIF(Table3[Sales Country],'Calcs for dash'!A46,Table3[Quantity Sold]) -> 1662800
A47: Russia | B47: =SUMIF(Table3[Sales Country],'Calcs for dash'!A47,Table3[Quantity Sold]) -> 488834
A48: Latvia | B48: =SUMIF(Table3[Sales Country],'Calcs for dash'!A48,Table3[Quantity Sold]) -> 341920
A49: Lithuania | B49: =SUMIF(Table3[Sales Country],'Calcs for dash'!A49,Table3[Quantity Sold]) -> 163800
A50: Azerbaijan | B50: =SUMIF(Table3[Sales Country],'Calcs for dash'!A50,Table3[Quantity Sold]) -> 34560
G54: TOP 5 profitable bottles
B55: =Pivot1!B3 -> Sum of Total Cost (USD) | C55: =Pivot1!C3 -> Sum of Operating Profit (USD) | D55: Product profitability | H55: =D55 -> Product profitability | I55: Quantity Sold
A56: =Pivot1!A27 -> Bottle 42-КПШ | B56: =Pivot1!B27 -> 12505.941 | C56: =Pivot1!C27 -> 2842.8525 | D56: =C56/B56 -> 0.22732017 | F56: 1 | G56: =A56 -> Bottle 42-КПШ | H56: =D56 -> 0.22732017 | I56: =GETPIVOTDATA("Sum of Quantity Sold",Pivot1!$A$3,"Product","Bottle 42-КПШ") -> 110638
A57: =Pivot1!A8 -> Bottle 110-Ш-Green | B57: =Pivot1!B8 -> 186388.78 | C57: =Pivot1!C8 -> 26356.376 | D57: =C57/B57 -> 0.14140538 | F57: 2 | G57: =A57 -> Bottle 110-Ш-Green | H57: =D57 -> 0.14140538 | I57: =GETPIVOTDATA("Sum of Quantity Sold",Pivot1!$A$3,"Product","Bottle 110-Ш-Green") -> 1259104
A58: =Pivot1!A7 -> Bottle 110-Ш-Brown | B58: =Pivot1!B7 -> 77922.483 | C58: =Pivot1!C7 -> 10070.028 | D58: =C58/B58 -> 0.12923135 | F58: 3 | G58: =A58 -> Bottle 110-Ш-Brown | H58: =D58 -> 0.12923135 | I58: =GETPIVOTDATA("Sum of Quantity Sold",Pivot1!$A$3,"Product","Bottle 110-Ш-Brown") -> 520772
A59: =Pivot1!A21 -> Bottle 140-КПМ | B59: =Pivot1!B21 -> 14530.593 | C59: =Pivot1!C21 -> 1736.4414 | D59: =C59/B59 -> 0.11950244 | F59: 4 | G59: =A59 -> Bottle 140-КПМ | H59: =D59 -> 0.11950244 | I59: =GETPIVOTDATA("Sum of Quantity Sold",Pivot1!$A$3,"Product","Bottle 140-КПМ") -> 117936
A60: =Pivot1!A26 -> Bottle 32-П-29-Б | B60: =Pivot1!B26 -> 4162.8034 | C60: =Pivot1!C26 -> 484.92069 | D60: =C60/B60 -> 0.11648897 | F60: 5 | G60: =A60 -> Bottle 32-П-29-Б | H60: =D60 -> 0.11648897 | I60: =GETPIVOTDATA("Sum of Quantity Sold",Pivot1!$A$3,"Product","Bottle 32-П-29-Б") -> 37440
A61: =Pivot1!A29 -> Bottle 29-В | B61: =Pivot1!B29 -> 53504.262 | C61: =Pivot1!C29 -> 5706.6621 | D61: =C61/B61 -> 0.10665808
A62: =Pivot1!A25 -> Bottle 32-П-29-А-700 | B62: =Pivot1!B25 -> 64108.294 | C62: =Pivot1!C25 -> 6231.3987 | D62: =C62/B62 -> 0.09720113
A63: =Pivot1!A17 -> Bottle 127-П-29-Б-700 | B63: =Pivot1!B17 -> 19875.776 | C63: =Pivot1!C17 -> 1809.569 | D63: =C63/B63 -> 0.091043941
A64: =Pivot1!A11 -> Bottle 117-П | B64: =Pivot1!B11 -> 14594.203 | C64: =Pivot1!C11 -> 1099.3138 | D64: =C64/B64 -> 0.075325371 | G64: TOP 5 loss-making bottles
A65: =Pivot1!A4 -> Bottle 103-ВВК | B65: =Pivot1!B4 -> 4099.669 | C65: =Pivot1!C4 -> 302.88276 | D65: =C65/B65 -> 0.073879809 | F65: 1 | G65: =A81 -> Bottle 118-ВВК | H65: =D81 -> -0.084300264 | I65: =GETPIVOTDATA("Sum of Quantity Sold",Pivot1!$A$3,"Product","Bottle 118-ВВК") -> 524312
A66: =Pivot1!A18 -> Bottle 128-КПН-М | B66: =Pivot1!B18 -> 29037.344 | C66: =Pivot1!C18 -> 2034.5523 | D66: =C66/B66 -> 0.070066747 | F66: 2 | G66: =A80 -> Bottle 81-КПМ | H66: =D80 -> -0.056153795 | I66: =GETPIVOTDATA("Sum of Quantity Sold",Pivot1!$A$3,"Product","Bottle 81-КПМ") -> 119340
A67: =Pivot1!A20 -> Bottle 139-КНд | B67: =Pivot1!B20 -> 42333.034 | C67: =Pivot1!C20 -> 2732.6759 | D67: =C67/B67 -> 0.064551854 | F67: 3 | G67: =A79 -> Bottle 138-КПНн | H67: =D79 -> -0.047496941 | I67: =GETPIVOTDATA("Sum of Quantity Sold",Pivot1!$A$3,"Product","Bottle 138-КПНн") -> 195776
A68: =Pivot1!A15 -> Bottle 125-В | B68: =Pivot1!B15 -> 98488.85 | C68: =Pivot1!C15 -> 5745.9781 | D68: =C68/B68 -> 0.058341407 | F68: 4 | G68: =A78 -> Bottle 11-ВКП-2 | H68: =D78 -> -0.041501709 | I68: =GETPIVOTDATA("Sum of Quantity Sold",Pivot1!$A$3,"Product","Bottle 11-ВКП-2") -> 198956
A69: =Pivot1!A24 -> Bottle 31-П-29-Б | B69: =Pivot1!B24 -> 2119.9655 | C69: =Pivot1!C24 -> 119.17241 | D69: =C69/B69 -> 0.056214317 | F69: 5 | G69: =A77 -> Bottle 111-В | H69: =D77 -> -0.034024747 | I69: =GETPIVOTDATA("Sum of Quantity Sold",Pivot1!$A$3,"Product","Bottle 111-В") -> 296400
A70: =Pivot1!A14 -> Bottle 123-КПШ | B70: =Pivot1!B14 -> 106022.03 | C70: =Pivot1!C14 -> 5504.1552 | D70: =C70/B70 -> 0.051915202
...

Sheet Pivot1
A3: Row Labels | B3: Sum of Total Cost (USD) | C3: Sum of Operating Profit (USD) | D3: Sum of Quantity Sold
A4: Bottle 103-ВВК | B4: 4099.669 | C4: 302.88276 | D4: 31140
A5: Bottle 109-А | B5: 13335.224 | C5: 406.43149 | D5: 136420
A6: Bottle 110-Ш | B6: 5081.0517 | C6: 155.52759 | D6: 29204
A7: Bottle 110-Ш-Brown | B7: 77922.483 | C7: 10070.028 | D7: 520772
A8: Bottle 110-Ш-Green | B8: 186388.78 | C8: 26356.376 | D8: 1259104
A9: Bottle 111-В | B9: 39148.572 | C9: -1332.0203 | D9: 296400
A10: Bottle 115-КПНб | B10: 80702.598 | C10: 4066.3676 | D10: 963980
A11: Bottle 117-П | B11: 14594.203 | C11: 1099.3138 | D11: 105840
A12: Bottle 118-ВВК | B12: 71078.984 | C12: -5991.9771 | D12: 524312
A13: Bottle 11-ВКП-2 | B13: 18168.082 | C13: -754.00646 | D13: 198956
A14: Bottle 123-КПШ | B14: 106022.03 | C14: 5504.1552 | D14: 550800
A15: Bottle 125-В | B15: 98488.85 | C15: 5745.9781 | D15: 863660
... A30: Grand Total | B30: 1058374.8 | C30: 65999.528 | D30: 8723726

Sheet Pivot2
A1: Row Labels | B1: Sum of Operating Profit (USD) | C1: Sum of Total Cost (USD)
A2: 0.375 | B2: 2842.8525 | C2: 12505.941
A3: 0.5 | B3: 6720.4276 | C3: 473386.12
A4: 0.568 | B4: -910.63702 | C4: 19172.54
A5: 0.7 | B5: 14042.312 | C5: 161181.64
A6: 0.75 | B6: 43304.572 | C6: 392128.52
A7: Grand Total | B7: 65999.528 | C7: 1058374.8
